2021-06-04 15:39:59,554 INFO    MainThread:9573 [internal.py:wandb_internal():88] W&B internal server running at pid: 9573, started at: 2021-06-04 15:39:59.554510
2021-06-04 15:39:59,555 INFO    WriterThread:9573 [datastore.py:open_for_write():77] open: /Users/arjunbhalla/Desktop/School/Grad/Research/intrinsic-video-factorisation/wandb/run-20210604_153957-3unwkbob/run-3unwkbob.wandb
2021-06-04 15:39:59,556 DEBUG   HandlerThread:9573 [handler.py:handle_request():121] handle_request: check_version
2021-06-04 15:39:59,557 DEBUG   SenderThread:9573 [sender.py:send():176] send: header
2021-06-04 15:39:59,557 DEBUG   SenderThread:9573 [sender.py:send_request():186] send_request: check_version
2021-06-04 15:39:59,596 DEBUG   SenderThread:9573 [sender.py:send():176] send: run
2021-06-04 15:39:59,693 ERROR   SenderThread:9573 [internal_api.py:execute():130] 404 response executing GraphQL.
2021-06-04 15:39:59,693 ERROR   SenderThread:9573 [internal_api.py:execute():131] {"errors":[{"message":"project not found","path":["upsertBucket"]}],"data":{"upsertBucket":null}}
2021-06-04 15:40:00,601 INFO    HandlerThread:9573 [handler.py:finish():632] shutting down handler
2021-06-04 15:40:00,601 INFO    WriterThread:9573 [datastore.py:close():258] close: /Users/arjunbhalla/Desktop/School/Grad/Research/intrinsic-video-factorisation/wandb/run-20210604_153957-3unwkbob/run-3unwkbob.wandb
2021-06-04 15:40:00,601 ERROR   MainThread:9573 [internal.py:wandb_internal():159] Thread SenderThread:
Traceback (most recent call last):
  File "/Users/arjunbhalla/opt/anaconda3/envs/video-factorisation/lib/python3.8/site-packages/wandb/sdk/lib/retry.py", line 102, in __call__
    result = self._call_fn(*args, **kwargs)
  File "/Users/arjunbhalla/opt/anaconda3/envs/video-factorisation/lib/python3.8/site-packages/wandb/sdk/internal/internal_api.py", line 133, in execute
    six.reraise(*sys.exc_info())
  File "/Users/arjunbhalla/opt/anaconda3/envs/video-factorisation/lib/python3.8/site-packages/six.py", line 703, in reraise
    raise value
  File "/Users/arjunbhalla/opt/anaconda3/envs/video-factorisation/lib/python3.8/site-packages/wandb/sdk/internal/internal_api.py", line 127, in execute
    return self.client.execute(*args, **kwargs)
  File "/Users/arjunbhalla/opt/anaconda3/envs/video-factorisation/lib/python3.8/site-packages/wandb/vendor/gql-0.2.0/gql/client.py", line 52, in execute
    result = self._get_result(document, *args, **kwargs)
  File "/Users/arjunbhalla/opt/anaconda3/envs/video-factorisation/lib/python3.8/site-packages/wandb/vendor/gql-0.2.0/gql/client.py", line 60, in _get_result
    return self.transport.execute(document, *args, **kwargs)
  File "/Users/arjunbhalla/opt/anaconda3/envs/video-factorisation/lib/python3.8/site-packages/wandb/vendor/gql-0.2.0/gql/transport/requests.py", line 39, in execute
    request.raise_for_status()
  File "/Users/arjunbhalla/opt/anaconda3/envs/video-factorisation/lib/python3.8/site-packages/requests/models.py", line 943, in raise_for_status
    raise HTTPError(http_error_msg, response=self)
requests.exceptions.HTTPError: 404 Client Error: Not Found for url: https://api.wandb.ai/graphql

During handling of the above exception, another exception occurred:

Traceback (most recent call last):
  File "/Users/arjunbhalla/opt/anaconda3/envs/video-factorisation/lib/python3.8/site-packages/wandb/apis/normalize.py", line 24, in wrapper
    return func(*args, **kwargs)
  File "/Users/arjunbhalla/opt/anaconda3/envs/video-factorisation/lib/python3.8/site-packages/wandb/sdk/internal/internal_api.py", line 889, in upsert_run
    response = self.gql(mutation, variable_values=variable_values, **kwargs)
  File "/Users/arjunbhalla/opt/anaconda3/envs/video-factorisation/lib/python3.8/site-packages/wandb/sdk/lib/retry.py", line 118, in __call__
    if not check_retry_fn(e):
  File "/Users/arjunbhalla/opt/anaconda3/envs/video-factorisation/lib/python3.8/site-packages/wandb/util.py", line 717, in no_retry_auth
    raise CommError("Permission denied, ask the project owner to grant you access")
wandb.errors.CommError: Permission denied, ask the project owner to grant you access

During handling of the above exception, another exception occurred:

Traceback (most recent call last):
  File "/Users/arjunbhalla/opt/anaconda3/envs/video-factorisation/lib/python3.8/site-packages/wandb/sdk/internal/internal_util.py", line 55, in run
    self._run()
  File "/Users/arjunbhalla/opt/anaconda3/envs/video-factorisation/lib/python3.8/site-packages/wandb/sdk/internal/internal_util.py", line 105, in _run
    self._process(record)
  File "/Users/arjunbhalla/opt/anaconda3/envs/video-factorisation/lib/python3.8/site-packages/wandb/sdk/internal/internal.py", line 292, in _process
    self._sm.send(record)
  File "/Users/arjunbhalla/opt/anaconda3/envs/video-factorisation/lib/python3.8/site-packages/wandb/sdk/internal/sender.py", line 178, in send
    send_handler(record)
  File "/Users/arjunbhalla/opt/anaconda3/envs/video-factorisation/lib/python3.8/site-packages/wandb/sdk/internal/sender.py", line 586, in send_run
    self._init_run(run, config_value_dict)
  File "/Users/arjunbhalla/opt/anaconda3/envs/video-factorisation/lib/python3.8/site-packages/wandb/sdk/internal/sender.py", line 608, in _init_run
    server_run, inserted = self._api.upsert_run(
  File "/Users/arjunbhalla/opt/anaconda3/envs/video-factorisation/lib/python3.8/site-packages/wandb/apis/normalize.py", line 62, in wrapper
    six.reraise(CommError, CommError(message, err), sys.exc_info()[2])
  File "/Users/arjunbhalla/opt/anaconda3/envs/video-factorisation/lib/python3.8/site-packages/six.py", line 702, in reraise
    raise value.with_traceback(tb)
  File "/Users/arjunbhalla/opt/anaconda3/envs/video-factorisation/lib/python3.8/site-packages/wandb/apis/normalize.py", line 24, in wrapper
    return func(*args, **kwargs)
  File "/Users/arjunbhalla/opt/anaconda3/envs/video-factorisation/lib/python3.8/site-packages/wandb/sdk/internal/internal_api.py", line 889, in upsert_run
    response = self.gql(mutation, variable_values=variable_values, **kwargs)
  File "/Users/arjunbhalla/opt/anaconda3/envs/video-factorisation/lib/python3.8/site-packages/wandb/sdk/lib/retry.py", line 118, in __call__
    if not check_retry_fn(e):
  File "/Users/arjunbhalla/opt/anaconda3/envs/video-factorisation/lib/python3.8/site-packages/wandb/util.py", line 717, in no_retry_auth
    raise CommError("Permission denied, ask the project owner to grant you access")
wandb.errors.CommError: Permission denied, ask the project owner to grant you access
2021-06-04 15:40:00,657 INFO    MainThread:9573 [internal.py:handle_exit():78] Internal process exited
